Using python 3.8 to install /opt/stack/devstack/tools/dbcounter
+inc/python:pip_install:188                sudo -H LC_ALL=en_US.UTF-8 SETUPTOOLS_USE_DISTUTILS=stdlib http_proxy= https_proxy= no_proxy= PIP_FIND_LINKS= python3.8 -m pip install -c /opt/stack/requirements/upper-constraints.txt /opt/stack/devstack/tools/dbcounter
Processing ./tools/dbcounter
  Installing build dependencies ... error
  ERROR: Command errored out with exit status 1:
   command: /usr/bin/python3.8 /usr/lib/python3/dist-packages/pip install --ignore-installed --no-user --prefix /tmp/pip-build-env-05pz37up/overlay --no-warn-script-location --no-binary :none: --only-binary :none: -i https://pypi.org/simple -- sqlalchemy 'setuptools>=42'
       cwd: None
  Complete output (59 lines):
  Traceback (most recent call last):
    File "/usr/lib/python3.8/runpy.py", line 194, in _run_module_as_main
      return _run_code(code, main_globals, None,
    File "/usr/lib/python3.8/runpy.py", line 87, in _run_code
      exec(code, run_globals)
    File "/usr/lib/python3/dist-packages/pip/__main__.py", line 16, in <module>
      from pip._internal.cli.main import main as _main  # isort:skip # noqa
    File "/usr/lib/python3/dist-packages/pip/_internal/cli/main.py", line 10, in <module>
      from pip._internal.cli.autocompletion import autocomplete
    File "/usr/lib/python3/dist-packages/pip/_internal/cli/autocompletion.py", line 9, in <module>
      from pip._internal.cli.main_parser import create_main_parser
    File "/usr/lib/python3/dist-packages/pip/_internal/cli/main_parser.py", line 7, in <module>
      from pip._internal.cli import cmdoptions
    File "/usr/lib/python3/dist-packages/pip/_internal/cli/cmdoptions.py", line 24, in <module>
      from pip._internal.exceptions import CommandError
    File "/usr/lib/python3/dist-packages/pip/_internal/exceptions.py", line 10, in <module>
      from pip._vendor.six import iteritems
    File "/usr/lib/python3/dist-packages/pip/_vendor/__init__.py", line 65, in <module>
      vendored("cachecontrol")
    File "/usr/lib/python3/dist-packages/pip/_vendor/__init__.py", line 36, in vendored
      __import__(modulename, globals(), locals(), level=0)
    File "<frozen importlib._bootstrap>", line 991, in _find_and_load
    File "<frozen importlib._bootstrap>", line 975, in _find_and_load_unlocked
    File "<frozen importlib._bootstrap>", line 655, in _load_unlocked
    File "<frozen importlib._bootstrap>", line 618, in _load_backward_compatible
    File "<frozen zipimport>", line 259, in load_module
    File "/usr/share/python-wheels/CacheControl-0.12.6-py2.py3-none-any.whl/cachecontrol/__init__.py", line 9, in <module>
  
    File "<frozen importlib._bootstrap>", line 991, in _find_and_load
    File "<frozen importlib._bootstrap>", line 975, in _find_and_load_unlocked
    File "<frozen importlib._bootstrap>", line 655, in _load_unlocked
    File "<frozen importlib._bootstrap>", line 618, in _load_backward_compatible
    File "<frozen zipimport>", line 259, in load_module
    File "/usr/share/python-wheels/CacheControl-0.12.6-py2.py3-none-any.whl/cachecontrol/wrapper.py", line 1, in <module>
    File "<frozen importlib._bootstrap>", line 991, in _find_and_load
    File "<frozen importlib._bootstrap>", line 975, in _find_and_load_unlocked
    File "<frozen importlib._bootstrap>", line 655, in _load_unlocked
    File "<frozen importlib._bootstrap>", line 618, in _load_backward_compatible
    File "<frozen zipimport>", line 259, in load_module
    File "/usr/share/python-wheels/CacheControl-0.12.6-py2.py3-none-any.whl/cachecontrol/adapter.py", line 5, in <module>
    File "<frozen importlib._bootstrap>", line 991, in _find_and_load
    File "<frozen importlib._bootstrap>", line 975, in _find_and_load_unlocked
    File "<frozen importlib._bootstrap>", line 655, in _load_unlocked
    File "<frozen importlib._bootstrap>", line 618, in _load_backward_compatible
    File "<frozen zipimport>", line 259, in load_module
    File "/usr/share/python-wheels/requests-2.22.0-py2.py3-none-any.whl/requests/__init__.py", line 95, in <module>
    File "<frozen importlib._bootstrap>", line 991, in _find_and_load
    File "<frozen importlib._bootstrap>", line 975, in _find_and_load_unlocked
    File "<frozen importlib._bootstrap>", line 655, in _load_unlocked
    File "<frozen importlib._bootstrap>", line 618, in _load_backward_compatible
    File "<frozen zipimport>", line 259, in load_module
    File "/usr/share/python-wheels/urllib3-1.25.8-py2.py3-none-any.whl/urllib3/contrib/pyopenssl.py", line 46, in <module>
    File "/usr/local/lib/python3.8/dist-packages/OpenSSL/__init__.py", line 8, in <module>
      from OpenSSL import SSL, crypto
    File "/usr/local/lib/python3.8/dist-packages/OpenSSL/SSL.py", line 19, in <module>
      from OpenSSL.crypto import (
    File "/usr/local/lib/python3.8/dist-packages/OpenSSL/crypto.py", line 3258, in <module>
      utils.deprecated(
  TypeError: deprecated() got an unexpected keyword argument 'name'
  ----------------------------------------
ERROR: Command errored out with exit status 1: /usr/bin/python3.8 /usr/lib/python3/dist-packages/pip install --ignore-installed --no-user --prefix /tmp/pip-build-env-05pz37up/overlay --no-warn-script-location --no-binary :none: --only-binary :none: -i https://pypi.org/simple -- sqlalchemy 'setuptools>=42' Check the logs for full command output.
